<?xml version="1.0" ?>
<robot name="v4_6DoF">

<!-- ********** KINEMATIC PROPERTIES (JOINTS) ********** -->
<!-- I guess goal is all origin orientations all lined up when fully extended up -->
<joint name="world_joint" type="fixed">
    <parent link="world"/>
    <child link="base_link"/>
    <origin rpy="0.0 0.0 0.0" xyz="0.0 0.0 0.0"/>
</joint>

<!-- R1 -->
<joint name="joint1" type="continuous">
    <parent link="base_link"/>
    <child link="link1"/>
    <origin rpy="0.0 0.0 0.0" xyz="0.0 0.171375 0.0"/>
    <axis xyz="0 1 0"/>
</joint>

<!-- T1  rotated 90 degrees from R1-->
<joint name="joint2" type="continuous">
    <parent link="link1"/>
    <child link="link2"/>
    <origin rpy="0.0 0.0 1.570796325" xyz="0.0 0.0 0.0"/>
    <axis xyz="0 0 1"/>
</joint>

<!-- T2 -->
<joint name="joint3" type="continuous">
    <parent link="link2"/>
    <child link="link3"/>
    <origin rpy="0.0 0.0 -1.570796325" xyz="0.0 0.25 0"/>
    <axis xyz="0 0 1"/>
</joint>

<!-- R2 -->
<joint name="joint4" type="continuous">
    <parent link="link3"/>
    <child link="link4"/>
    <origin rpy="0.0 0.0 0.0" xyz="-0.06825 0.0 0.0"/>
    <axis xyz="0 1 0"/>
</joint>

<!-- T3 -->
<joint name="joint5" type="continuous">
    <parent link="link4"/>
    <child link="link5"/>
    <origin rpy="0.0 0.0 0.0" xyz="0.0 0.1783 0.0"/>
    <axis xyz="0 0 1"/>
</joint>

<joint name="joint6" type="continuous">
    <parent link="link5"/>
    <child link="link6"/>
    <origin rpy="0.0 0.0 0.0" xyz="0.0 0.0 0.0"/>
    <axis xyz="0 1 0"/>
</joint>

<joint name="ee_joint" type="fixed">
    <origin rpy="0 0 0" xyz="0 0.023282 0"/>
    <parent link="link6"/>
    <child link="ee_link"/>
</joint>

<!-- ********** INERTIAL PROPERTIES (LINKS) ********** -->
<link name="world"/>
<link name="base_link">
    <inertial>
        <mass value="4.0"/>
        <origin rpy="0 0 0" xyz="0.0 0.0 0.0"/>
        <inertia ixx="0.00443333156" ixy="0.0" ixz="0.0"
                 iyy="0.00443333156" iyz="0.0" izz="0.0072"/>
    </inertial>
</link>

<link name="link1">
    <inertial>
        <mass value="3.7"/>
        <origin rpy="0 0 0" xyz="0.0 0.0 0.0"/>
        <inertia ixx="0.010267495893" ixy="0.0" ixz="0.0"
                 iyy="0.010267495893" iyz="0.0" izz="0.00666"/>
    </inertial>
</link>

<link name="link2">
    <inertial>
        <mass value="3.7"/>
        <origin rpy="0 0 0" xyz="0.0 0.0 0.0"/>
        <inertia ixx="0.010267495893" ixy="0.0" ixz="0.0"
                 iyy="0.010267495893" iyz="0.0" izz="0.00666"/>
    </inertial>
</link>

<link name="link3">
    <inertial>
        <mass value="3.7"/>
        <origin rpy="0 0 0" xyz="0.0 0.0 0.0"/>
        <inertia ixx="0.010267495893" ixy="0.0" ixz="0.0"
                 iyy="0.010267495893" iyz="0.0" izz="0.00666"/>
    </inertial>
</link>

<link name="link4">
    <inertial>
        <mass value="3.7"/>
        <origin rpy="0 0 0" xyz="0.0 0.0 0.0"/>
        <inertia ixx="0.010267495893" ixy="0.0" ixz="0.0"
                 iyy="0.010267495893" iyz="0.0" izz="0.00666"/>
    </inertial>
</link>

<link name="link5">
    <inertial>
        <mass value="3.7"/>
        <origin rpy="0 0 0" xyz="0.0 0.0 0.0"/>
        <inertia ixx="0.010267495893" ixy="0.0" ixz="0.0"
                 iyy="0.010267495893" iyz="0.0" izz="0.00666"/>
    </inertial>
</link>

<link name="link6">
    <inertial>
        <mass value="3.7"/>
        <origin rpy="0 0 0" xyz="0.0 0.0 0.0"/>
        <inertia ixx="0.010267495893" ixy="0.0" ixz="0.0"
                 iyy="0.010267495893" iyz="0.0" izz="0.00666"/>
    </inertial>
</link>

<link name="ee_link"/>

</robot>